Error in file: /home/matias/Documents/UdeSA/CNC/diariziation_error_rate/UCSF_manual_prepro/UCSF__33362_04-03-24__PictureDescription.txt
Traceback (most recent call last):
  File "/tmp/ipykernel_68806/2489993138.py", line 29, in <module>
    hypothesis = txt2annotation(hypothesis_path, annotation)
  File "/tmp/ipykernel_68806/733004344.py", line 4, in txt2annotation
    with open(path_txt, 'r') as f:
  File "/home/matias/Documents/UdeSA/CNC/diariziation_error_rate/der_env/lib/python3.10/site-packages/IPython/core/interactiveshell.py", line 324, in _modified_open
    return io_open(file, *args, **kwargs)
FileNotFoundError: [Errno 2] No such file or directory: '/home/matias/Documents/UdeSA/CNC/diariziation_error_rate/UCSF_manual/UCSF__33362_04-03-24__PictureDescription.txt'


Error in file: /home/matias/Documents/UdeSA/CNC/diariziation_error_rate/UCSF_manual_prepro/UCSF__35173_01-17-25__PictureDescription.txt
Traceback (most recent call last):
  File "/tmp/ipykernel_68806/2489993138.py", line 29, in <module>
    hypothesis = txt2annotation(hypothesis_path, annotation)
  File "/tmp/ipykernel_68806/733004344.py", line 8, in txt2annotation
    start, end, speaker = line.split()
ValueError: not enough values to unpack (expected 3, got 2)


Error in file: /home/matias/Documents/UdeSA/CNC/diariziation_error_rate/UCSF_manual_prepro/UCSF__24651_06-24-24_PictureDescription.txt
Traceback (most recent call last):
  File "/tmp/ipykernel_68806/2489993138.py", line 29, in <module>
    hypothesis = txt2annotation(hypothesis_path, annotation)
  File "/tmp/ipykernel_68806/733004344.py", line 4, in txt2annotation
    with open(path_txt, 'r') as f:
  File "/home/matias/Documents/UdeSA/CNC/diariziation_error_rate/der_env/lib/python3.10/site-packages/IPython/core/interactiveshell.py", line 324, in _modified_open
    return io_open(file, *args, **kwargs)
FileNotFoundError: [Errno 2] No such file or directory: '/home/matias/Documents/UdeSA/CNC/diariziation_error_rate/UCSF_manual/UCSF__24651_06-24-24_PictureDescription.txt'


Error in file: /home/matias/Documents/UdeSA/CNC/diariziation_error_rate/UCSF_manual_prepro/UCSF__34682_10-15-24__PictureDescription.txt
Traceback (most recent call last):
  File "/tmp/ipykernel_68806/2489993138.py", line 29, in <module>
    hypothesis = txt2annotation(hypothesis_path, annotation)
  File "/tmp/ipykernel_68806/733004344.py", line 4, in txt2annotation
    with open(path_txt, 'r') as f:
  File "/home/matias/Documents/UdeSA/CNC/diariziation_error_rate/der_env/lib/python3.10/site-packages/IPython/core/interactiveshell.py", line 324, in _modified_open
    return io_open(file, *args, **kwargs)
FileNotFoundError: [Errno 2] No such file or directory: '/home/matias/Documents/UdeSA/CNC/diariziation_error_rate/UCSF_manual/UCSF__34682_10-15-24__PictureDescription.txt'


Error in file: /home/matias/Documents/UdeSA/CNC/diariziation_error_rate/UCSF_manual_prepro/UCSF__33362_09-11-24__PictureDescription.txt
Traceback (most recent call last):
  File "/tmp/ipykernel_68806/2489993138.py", line 29, in <module>
    hypothesis = txt2annotation(hypothesis_path, annotation)
  File "/tmp/ipykernel_68806/733004344.py", line 4, in txt2annotation
    with open(path_txt, 'r') as f:
  File "/home/matias/Documents/UdeSA/CNC/diariziation_error_rate/der_env/lib/python3.10/site-packages/IPython/core/interactiveshell.py", line 324, in _modified_open
    return io_open(file, *args, **kwargs)
FileNotFoundError: [Errno 2] No such file or directory: '/home/matias/Documents/UdeSA/CNC/diariziation_error_rate/UCSF_manual/UCSF__33362_09-11-24__PictureDescription.txt'


Error in file: /home/matias/Documents/UdeSA/CNC/diariziation_error_rate/UCSF_manual_prepro/UCSF__33723_02-20-25__PictureDescription.txt
Traceback (most recent call last):
  File "/tmp/ipykernel_68806/2489993138.py", line 29, in <module>
    hypothesis = txt2annotation(hypothesis_path, annotation)
  File "/tmp/ipykernel_68806/733004344.py", line 4, in txt2annotation
    with open(path_txt, 'r') as f:
  File "/home/matias/Documents/UdeSA/CNC/diariziation_error_rate/der_env/lib/python3.10/site-packages/IPython/core/interactiveshell.py", line 324, in _modified_open
    return io_open(file, *args, **kwargs)
FileNotFoundError: [Errno 2] No such file or directory: '/home/matias/Documents/UdeSA/CNC/diariziation_error_rate/UCSF_manual/UCSF__33723_02-20-25__PictureDescription.txt'


Error in file: /home/matias/Documents/UdeSA/CNC/diariziation_error_rate/UCSF_manual_prepro/UCSF__33362_04-03-24__PictureDescription.txt
Traceback (most recent call last):
  File "/tmp/ipykernel_68806/2130815559.py", line 28, in <module>
    hypothesis = txt2annotation(hypothesis_path, annotation)
  File "/tmp/ipykernel_68806/733004344.py", line 4, in txt2annotation
    with open(path_txt, 'r') as f:
  File "/home/matias/Documents/UdeSA/CNC/diariziation_error_rate/der_env/lib/python3.10/site-packages/IPython/core/interactiveshell.py", line 324, in _modified_open
    return io_open(file, *args, **kwargs)
FileNotFoundError: [Errno 2] No such file or directory: '/home/matias/Documents/UdeSA/CNC/diariziation_error_rate/UCSF_manual/UCSF__33362_04-03-24__PictureDescription.txt'


Error in file: /home/matias/Documents/UdeSA/CNC/diariziation_error_rate/UCSF_manual_prepro/UCSF__35173_01-17-25__PictureDescription.txt
Traceback (most recent call last):
  File "/tmp/ipykernel_68806/2130815559.py", line 28, in <module>
    hypothesis = txt2annotation(hypothesis_path, annotation)
  File "/tmp/ipykernel_68806/733004344.py", line 8, in txt2annotation
    start, end, speaker = line.split()
ValueError: not enough values to unpack (expected 3, got 2)


Error in file: /home/matias/Documents/UdeSA/CNC/diariziation_error_rate/UCSF_manual_prepro/UCSF__24651_06-24-24_PictureDescription.txt
Traceback (most recent call last):
  File "/tmp/ipykernel_68806/2130815559.py", line 28, in <module>
    hypothesis = txt2annotation(hypothesis_path, annotation)
  File "/tmp/ipykernel_68806/733004344.py", line 4, in txt2annotation
    with open(path_txt, 'r') as f:
  File "/home/matias/Documents/UdeSA/CNC/diariziation_error_rate/der_env/lib/python3.10/site-packages/IPython/core/interactiveshell.py", line 324, in _modified_open
    return io_open(file, *args, **kwargs)
FileNotFoundError: [Errno 2] No such file or directory: '/home/matias/Documents/UdeSA/CNC/diariziation_error_rate/UCSF_manual/UCSF__24651_06-24-24_PictureDescription.txt'


Error in file: /home/matias/Documents/UdeSA/CNC/diariziation_error_rate/UCSF_manual_prepro/UCSF__34682_10-15-24__PictureDescription.txt
Traceback (most recent call last):
  File "/tmp/ipykernel_68806/2130815559.py", line 28, in <module>
    hypothesis = txt2annotation(hypothesis_path, annotation)
  File "/tmp/ipykernel_68806/733004344.py", line 4, in txt2annotation
    with open(path_txt, 'r') as f:
  File "/home/matias/Documents/UdeSA/CNC/diariziation_error_rate/der_env/lib/python3.10/site-packages/IPython/core/interactiveshell.py", line 324, in _modified_open
    return io_open(file, *args, **kwargs)
FileNotFoundError: [Errno 2] No such file or directory: '/home/matias/Documents/UdeSA/CNC/diariziation_error_rate/UCSF_manual/UCSF__34682_10-15-24__PictureDescription.txt'


Error in file: /home/matias/Documents/UdeSA/CNC/diariziation_error_rate/UCSF_manual_prepro/UCSF__33362_09-11-24__PictureDescription.txt
Traceback (most recent call last):
  File "/tmp/ipykernel_68806/2130815559.py", line 28, in <module>
    hypothesis = txt2annotation(hypothesis_path, annotation)
  File "/tmp/ipykernel_68806/733004344.py", line 4, in txt2annotation
    with open(path_txt, 'r') as f:
  File "/home/matias/Documents/UdeSA/CNC/diariziation_error_rate/der_env/lib/python3.10/site-packages/IPython/core/interactiveshell.py", line 324, in _modified_open
    return io_open(file, *args, **kwargs)
FileNotFoundError: [Errno 2] No such file or directory: '/home/matias/Documents/UdeSA/CNC/diariziation_error_rate/UCSF_manual/UCSF__33362_09-11-24__PictureDescription.txt'


Error in file: /home/matias/Documents/UdeSA/CNC/diariziation_error_rate/UCSF_manual_prepro/UCSF__33723_02-20-25__PictureDescription.txt
Traceback (most recent call last):
  File "/tmp/ipykernel_68806/2130815559.py", line 28, in <module>
    hypothesis = txt2annotation(hypothesis_path, annotation)
  File "/tmp/ipykernel_68806/733004344.py", line 4, in txt2annotation
    with open(path_txt, 'r') as f:
  File "/home/matias/Documents/UdeSA/CNC/diariziation_error_rate/der_env/lib/python3.10/site-packages/IPython/core/interactiveshell.py", line 324, in _modified_open
    return io_open(file, *args, **kwargs)
FileNotFoundError: [Errno 2] No such file or directory: '/home/matias/Documents/UdeSA/CNC/diariziation_error_rate/UCSF_manual/UCSF__33723_02-20-25__PictureDescription.txt'


Error in file: /home/matias/Documents/UdeSA/CNC/diariziation_error_rate/UCSF_manual_prepro/UCSF__33362_04-03-24__PictureDescription.txt
Traceback (most recent call last):
  File "/tmp/ipykernel_68806/2130815559.py", line 28, in <module>
    hypothesis = txt2annotation(hypothesis_path, annotation)
  File "/tmp/ipykernel_68806/733004344.py", line 4, in txt2annotation
    with open(path_txt, 'r') as f:
  File "/home/matias/Documents/UdeSA/CNC/diariziation_error_rate/der_env/lib/python3.10/site-packages/IPython/core/interactiveshell.py", line 324, in _modified_open
    return io_open(file, *args, **kwargs)
FileNotFoundError: [Errno 2] No such file or directory: '/home/matias/Documents/UdeSA/CNC/diariziation_error_rate/UCSF_manual/UCSF__33362_04-03-24__PictureDescription.txt'


Error in file: /home/matias/Documents/UdeSA/CNC/diariziation_error_rate/UCSF_manual_prepro/UCSF__35173_01-17-25__PictureDescription.txt
Traceback (most recent call last):
  File "/tmp/ipykernel_68806/2130815559.py", line 28, in <module>
    hypothesis = txt2annotation(hypothesis_path, annotation)
  File "/tmp/ipykernel_68806/733004344.py", line 8, in txt2annotation
    start, end, speaker = line.split()
ValueError: not enough values to unpack (expected 3, got 2)


Error in file: /home/matias/Documents/UdeSA/CNC/diariziation_error_rate/UCSF_manual_prepro/UCSF__24651_06-24-24_PictureDescription.txt
Traceback (most recent call last):
  File "/tmp/ipykernel_68806/2130815559.py", line 28, in <module>
    hypothesis = txt2annotation(hypothesis_path, annotation)
  File "/tmp/ipykernel_68806/733004344.py", line 4, in txt2annotation
    with open(path_txt, 'r') as f:
  File "/home/matias/Documents/UdeSA/CNC/diariziation_error_rate/der_env/lib/python3.10/site-packages/IPython/core/interactiveshell.py", line 324, in _modified_open
    return io_open(file, *args, **kwargs)
FileNotFoundError: [Errno 2] No such file or directory: '/home/matias/Documents/UdeSA/CNC/diariziation_error_rate/UCSF_manual/UCSF__24651_06-24-24_PictureDescription.txt'


Error in file: /home/matias/Documents/UdeSA/CNC/diariziation_error_rate/UCSF_manual_prepro/UCSF__34682_10-15-24__PictureDescription.txt
Traceback (most recent call last):
  File "/tmp/ipykernel_68806/2130815559.py", line 28, in <module>
    hypothesis = txt2annotation(hypothesis_path, annotation)
  File "/tmp/ipykernel_68806/733004344.py", line 4, in txt2annotation
    with open(path_txt, 'r') as f:
  File "/home/matias/Documents/UdeSA/CNC/diariziation_error_rate/der_env/lib/python3.10/site-packages/IPython/core/interactiveshell.py", line 324, in _modified_open
    return io_open(file, *args, **kwargs)
FileNotFoundError: [Errno 2] No such file or directory: '/home/matias/Documents/UdeSA/CNC/diariziation_error_rate/UCSF_manual/UCSF__34682_10-15-24__PictureDescription.txt'


Error in file: /home/matias/Documents/UdeSA/CNC/diariziation_error_rate/UCSF_manual_prepro/UCSF__33362_09-11-24__PictureDescription.txt
Traceback (most recent call last):
  File "/tmp/ipykernel_68806/2130815559.py", line 28, in <module>
    hypothesis = txt2annotation(hypothesis_path, annotation)
  File "/tmp/ipykernel_68806/733004344.py", line 4, in txt2annotation
    with open(path_txt, 'r') as f:
  File "/home/matias/Documents/UdeSA/CNC/diariziation_error_rate/der_env/lib/python3.10/site-packages/IPython/core/interactiveshell.py", line 324, in _modified_open
    return io_open(file, *args, **kwargs)
FileNotFoundError: [Errno 2] No such file or directory: '/home/matias/Documents/UdeSA/CNC/diariziation_error_rate/UCSF_manual/UCSF__33362_09-11-24__PictureDescription.txt'


Error in file: /home/matias/Documents/UdeSA/CNC/diariziation_error_rate/UCSF_manual_prepro/UCSF__33723_02-20-25__PictureDescription.txt
Traceback (most recent call last):
  File "/tmp/ipykernel_68806/2130815559.py", line 28, in <module>
    hypothesis = txt2annotation(hypothesis_path, annotation)
  File "/tmp/ipykernel_68806/733004344.py", line 4, in txt2annotation
    with open(path_txt, 'r') as f:
  File "/home/matias/Documents/UdeSA/CNC/diariziation_error_rate/der_env/lib/python3.10/site-packages/IPython/core/interactiveshell.py", line 324, in _modified_open
    return io_open(file, *args, **kwargs)
FileNotFoundError: [Errno 2] No such file or directory: '/home/matias/Documents/UdeSA/CNC/diariziation_error_rate/UCSF_manual/UCSF__33723_02-20-25__PictureDescription.txt'


Error in file: /home/matias/Documents/UdeSA/CNC/diariziation_error_rate/UCSF_manual_prepro/UCSF__35173_01-17-25__PictureDescription.txt
Traceback (most recent call last):
  File "/tmp/ipykernel_68806/2130815559.py", line 28, in <module>
    hypothesis = txt2annotation(hypothesis_path, annotation)
  File "/tmp/ipykernel_68806/733004344.py", line 8, in txt2annotation
    start, end, speaker = line.split()
ValueError: not enough values to unpack (expected 3, got 2)


Error in file: /home/matias/Documents/UdeSA/CNC/diariziation_error_rate/UCSF_manual_prepro/UCSF__24651_06-24-24_PictureDescription.txt
Traceback (most recent call last):
  File "/tmp/ipykernel_68806/2130815559.py", line 28, in <module>
    hypothesis = txt2annotation(hypothesis_path, annotation)
  File "/tmp/ipykernel_68806/733004344.py", line 4, in txt2annotation
    with open(path_txt, 'r') as f:
  File "/home/matias/Documents/UdeSA/CNC/diariziation_error_rate/der_env/lib/python3.10/site-packages/IPython/core/interactiveshell.py", line 324, in _modified_open
    return io_open(file, *args, **kwargs)
FileNotFoundError: [Errno 2] No such file or directory: '/home/matias/Documents/UdeSA/CNC/diariziation_error_rate/UCSF_manual/UCSF__24651_06-24-24_PictureDescription.txt'


Error in file: /home/matias/Documents/UdeSA/CNC/diariziation_error_rate/UCSF_manual_prepro/UCSF__6909_ 01-24-25__PictureDescription.txt
Traceback (most recent call last):
  File "/tmp/ipykernel_68806/2130815559.py", line 28, in <module>
    hypothesis = txt2annotation(hypothesis_path, annotation)
  File "/tmp/ipykernel_68806/733004344.py", line 4, in txt2annotation
    with open(path_txt, 'r') as f:
  File "/home/matias/Documents/UdeSA/CNC/diariziation_error_rate/der_env/lib/python3.10/site-packages/IPython/core/interactiveshell.py", line 324, in _modified_open
    return io_open(file, *args, **kwargs)
FileNotFoundError: [Errno 2] No such file or directory: '/home/matias/Documents/UdeSA/CNC/diariziation_error_rate/UCSF_manual/UCSF__6909_ 01-24-25__PictureDescription.txt'


Error in file: /home/matias/Documents/UdeSA/CNC/diariziation_error_rate/UCSF_manual_prepro/UCSF__6909_06-14-24__PictureDescription.txt
Traceback (most recent call last):
  File "/tmp/ipykernel_68806/2130815559.py", line 28, in <module>
    hypothesis = txt2annotation(hypothesis_path, annotation)
  File "/tmp/ipykernel_68806/733004344.py", line 4, in txt2annotation
    with open(path_txt, 'r') as f:
  File "/home/matias/Documents/UdeSA/CNC/diariziation_error_rate/der_env/lib/python3.10/site-packages/IPython/core/interactiveshell.py", line 324, in _modified_open
    return io_open(file, *args, **kwargs)
FileNotFoundError: [Errno 2] No such file or directory: '/home/matias/Documents/UdeSA/CNC/diariziation_error_rate/UCSF_manual/UCSF__6909_06-14-24__PictureDescription.txt'


Error in file: /home/matias/Documents/UdeSA/CNC/diariziation_error_rate/UCSF_manual_prepro/UCSF__24651_06-24-24_PictureDescription.txt
Traceback (most recent call last):
  File "/tmp/ipykernel_68806/2130815559.py", line 28, in <module>
    hypothesis = txt2annotation(hypothesis_path, annotation)
  File "/tmp/ipykernel_68806/733004344.py", line 4, in txt2annotation
    with open(path_txt, 'r') as f:
  File "/home/matias/Documents/UdeSA/CNC/diariziation_error_rate/der_env/lib/python3.10/site-packages/IPython/core/interactiveshell.py", line 324, in _modified_open
    return io_open(file, *args, **kwargs)
FileNotFoundError: [Errno 2] No such file or directory: '/home/matias/Documents/UdeSA/CNC/diariziation_error_rate/UCSF_manual/UCSF__24651_06-24-24_PictureDescription.txt'


Error in file: /home/matias/Documents/UdeSA/CNC/diariziation_error_rate/UCSF_manual_prepro/UCSF__6909_ 01-24-25__PictureDescription.txt
Traceback (most recent call last):
  File "/tmp/ipykernel_68806/2130815559.py", line 28, in <module>
    hypothesis = txt2annotation(hypothesis_path, annotation)
  File "/tmp/ipykernel_68806/733004344.py", line 4, in txt2annotation
    with open(path_txt, 'r') as f:
  File "/home/matias/Documents/UdeSA/CNC/diariziation_error_rate/der_env/lib/python3.10/site-packages/IPython/core/interactiveshell.py", line 324, in _modified_open
    return io_open(file, *args, **kwargs)
FileNotFoundError: [Errno 2] No such file or directory: '/home/matias/Documents/UdeSA/CNC/diariziation_error_rate/UCSF_manual/UCSF__6909_ 01-24-25__PictureDescription.txt'


Error in file: /home/matias/Documents/UdeSA/CNC/diariziation_error_rate/UCSF_manual_prepro/UCSF__6909_06-14-24__PictureDescription.txt
Traceback (most recent call last):
  File "/tmp/ipykernel_68806/2130815559.py", line 28, in <module>
    hypothesis = txt2annotation(hypothesis_path, annotation)
  File "/tmp/ipykernel_68806/733004344.py", line 4, in txt2annotation
    with open(path_txt, 'r') as f:
  File "/home/matias/Documents/UdeSA/CNC/diariziation_error_rate/der_env/lib/python3.10/site-packages/IPython/core/interactiveshell.py", line 324, in _modified_open
    return io_open(file, *args, **kwargs)
FileNotFoundError: [Errno 2] No such file or directory: '/home/matias/Documents/UdeSA/CNC/diariziation_error_rate/UCSF_manual/UCSF__6909_06-14-24__PictureDescription.txt'


Error in file: /home/matias/Documents/UdeSA/CNC/diariziation_error_rate/UCSF_manual_prepro/UCSF__24651_06-24-24_PictureDescription.txt
Traceback (most recent call last):
  File "/tmp/ipykernel_68806/2130815559.py", line 28, in <module>
    hypothesis = txt2annotation(hypothesis_path, annotation)
  File "/tmp/ipykernel_68806/733004344.py", line 4, in txt2annotation
    with open(path_txt, 'r') as f:
  File "/home/matias/Documents/UdeSA/CNC/diariziation_error_rate/der_env/lib/python3.10/site-packages/IPython/core/interactiveshell.py", line 324, in _modified_open
    return io_open(file, *args, **kwargs)
FileNotFoundError: [Errno 2] No such file or directory: '/home/matias/Documents/UdeSA/CNC/diariziation_error_rate/UCSF_manual/UCSF__24651_06-24-24_PictureDescription.txt'


Error in file: /home/matias/Documents/UdeSA/CNC/diariziation_error_rate/UCSF_manual_prepro/UCSF__6909_ 01-24-25__PictureDescription.txt
Traceback (most recent call last):
  File "/tmp/ipykernel_68806/2130815559.py", line 28, in <module>
    hypothesis = txt2annotation(hypothesis_path, annotation)
  File "/tmp/ipykernel_68806/733004344.py", line 4, in txt2annotation
    with open(path_txt, 'r') as f:
  File "/home/matias/Documents/UdeSA/CNC/diariziation_error_rate/der_env/lib/python3.10/site-packages/IPython/core/interactiveshell.py", line 324, in _modified_open
    return io_open(file, *args, **kwargs)
FileNotFoundError: [Errno 2] No such file or directory: '/home/matias/Documents/UdeSA/CNC/diariziation_error_rate/UCSF_manual/UCSF__6909_ 01-24-25__PictureDescription.txt'


Error in file: /home/matias/Documents/UdeSA/CNC/diariziation_error_rate/UCSF_manual_prepro/UCSF__6909_06-14-24__PictureDescription.txt
Traceback (most recent call last):
  File "/tmp/ipykernel_68806/2130815559.py", line 28, in <module>
    hypothesis = txt2annotation(hypothesis_path, annotation)
  File "/tmp/ipykernel_68806/733004344.py", line 4, in txt2annotation
    with open(path_txt, 'r') as f:
  File "/home/matias/Documents/UdeSA/CNC/diariziation_error_rate/der_env/lib/python3.10/site-packages/IPython/core/interactiveshell.py", line 324, in _modified_open
    return io_open(file, *args, **kwargs)
FileNotFoundError: [Errno 2] No such file or directory: '/home/matias/Documents/UdeSA/CNC/diariziation_error_rate/UCSF_manual/UCSF__6909_06-14-24__PictureDescription.txt'


Error in file: /home/matias/Documents/UdeSA/CNC/diariziation_error_rate/UCSF_manual_prepro/UCSF__24651_06-24-24_PictureDescription.txt
Traceback (most recent call last):
  File "/tmp/ipykernel_68806/2130815559.py", line 28, in <module>
    hypothesis = txt2annotation(hypothesis_path, annotation)
  File "/tmp/ipykernel_68806/733004344.py", line 4, in txt2annotation
    with open(path_txt, 'r') as f:
  File "/home/matias/Documents/UdeSA/CNC/diariziation_error_rate/der_env/lib/python3.10/site-packages/IPython/core/interactiveshell.py", line 324, in _modified_open
    return io_open(file, *args, **kwargs)
FileNotFoundError: [Errno 2] No such file or directory: '/home/matias/Documents/UdeSA/CNC/diariziation_error_rate/UCSF_manual/UCSF__24651_06-24-24_PictureDescription.txt'


Error in file: /home/matias/Documents/UdeSA/CNC/diariziation_error_rate/UCSF_manual_prepro/UCSF__6909_ 01-24-25__PictureDescription.txt
Traceback (most recent call last):
  File "/tmp/ipykernel_68806/2130815559.py", line 28, in <module>
    hypothesis = txt2annotation(hypothesis_path, annotation)
  File "/tmp/ipykernel_68806/733004344.py", line 4, in txt2annotation
    with open(path_txt, 'r') as f:
  File "/home/matias/Documents/UdeSA/CNC/diariziation_error_rate/der_env/lib/python3.10/site-packages/IPython/core/interactiveshell.py", line 324, in _modified_open
    return io_open(file, *args, **kwargs)
FileNotFoundError: [Errno 2] No such file or directory: '/home/matias/Documents/UdeSA/CNC/diariziation_error_rate/UCSF_manual/UCSF__6909_ 01-24-25__PictureDescription.txt'


Error in file: /home/matias/Documents/UdeSA/CNC/diariziation_error_rate/UCSF_manual_prepro/UCSF__6909_06-14-24__PictureDescription.txt
Traceback (most recent call last):
  File "/tmp/ipykernel_68806/2130815559.py", line 28, in <module>
    hypothesis = txt2annotation(hypothesis_path, annotation)
  File "/tmp/ipykernel_68806/733004344.py", line 4, in txt2annotation
    with open(path_txt, 'r') as f:
  File "/home/matias/Documents/UdeSA/CNC/diariziation_error_rate/der_env/lib/python3.10/site-packages/IPython/core/interactiveshell.py", line 324, in _modified_open
    return io_open(file, *args, **kwargs)
FileNotFoundError: [Errno 2] No such file or directory: '/home/matias/Documents/UdeSA/CNC/diariziation_error_rate/UCSF_manual/UCSF__6909_06-14-24__PictureDescription.txt'


Error in file: /home/matias/Documents/UdeSA/CNC/diariziation_error_rate/UCSF_manual_prepro/UCSF__24651_06-24-24_PictureDescription.txt
Traceback (most recent call last):
  File "/tmp/ipykernel_68806/2130815559.py", line 28, in <module>
    hypothesis = txt2annotation(hypothesis_path, annotation)
  File "/tmp/ipykernel_68806/733004344.py", line 4, in txt2annotation
    with open(path_txt, 'r') as f:
  File "/home/matias/Documents/UdeSA/CNC/diariziation_error_rate/der_env/lib/python3.10/site-packages/IPython/core/interactiveshell.py", line 324, in _modified_open
    return io_open(file, *args, **kwargs)
FileNotFoundError: [Errno 2] No such file or directory: '/home/matias/Documents/UdeSA/CNC/diariziation_error_rate/UCSF_manual/UCSF__24651_06-24-24_PictureDescription.txt'


Error in file: /home/matias/Documents/UdeSA/CNC/diariziation_error_rate/UCSF_manual_prepro/UCSF__12029_03-14-24__PictureDescription.txt
Traceback (most recent call last):
  File "/tmp/ipykernel_43805/769737209.py", line 17, in <module>
    annotation = Annotation(uri=file)
NameError: name 'Annotation' is not defined


Error in file: /home/matias/Documents/UdeSA/CNC/diariziation_error_rate/UCSF_manual_prepro/UCSF__35138_01-31-25__PictureDescription.txt
Traceback (most recent call last):
  File "/tmp/ipykernel_43805/769737209.py", line 17, in <module>
    annotation = Annotation(uri=file)
NameError: name 'Annotation' is not defined


Error in file: /home/matias/Documents/UdeSA/CNC/diariziation_error_rate/UCSF_manual_prepro/UCSF__35066_02-01-24__PictureDescription.txt
Traceback (most recent call last):
  File "/tmp/ipykernel_43805/769737209.py", line 17, in <module>
    annotation = Annotation(uri=file)
NameError: name 'Annotation' is not defined


Error in file: /home/matias/Documents/UdeSA/CNC/diariziation_error_rate/UCSF_manual_prepro/UCSF__33237_09-09-24__PictureDescription.txt
Traceback (most recent call last):
  File "/tmp/ipykernel_43805/769737209.py", line 17, in <module>
    annotation = Annotation(uri=file)
NameError: name 'Annotation' is not defined


Error in file: /home/matias/Documents/UdeSA/CNC/diariziation_error_rate/UCSF_manual_prepro/UCSF__33362_02-14-25__PictureDescription.txt
Traceback (most recent call last):
  File "/tmp/ipykernel_43805/769737209.py", line 17, in <module>
    annotation = Annotation(uri=file)
NameError: name 'Annotation' is not defined


Error in file: /home/matias/Documents/UdeSA/CNC/diariziation_error_rate/UCSF_manual_prepro/UCSF__35416_12-09-24__PictureDescription.txt
Traceback (most recent call last):
  File "/tmp/ipykernel_43805/769737209.py", line 17, in <module>
    annotation = Annotation(uri=file)
NameError: name 'Annotation' is not defined


Error in file: /home/matias/Documents/UdeSA/CNC/diariziation_error_rate/UCSF_manual_prepro/UCSF__33892_01-22-25__PictureDescription.txt
Traceback (most recent call last):
  File "/tmp/ipykernel_43805/769737209.py", line 17, in <module>
    annotation = Annotation(uri=file)
NameError: name 'Annotation' is not defined


Error in file: /home/matias/Documents/UdeSA/CNC/diariziation_error_rate/UCSF_manual_prepro/UCSF__34302_04-09-24__PictureDescription.txt
Traceback (most recent call last):
  File "/tmp/ipykernel_43805/769737209.py", line 17, in <module>
    annotation = Annotation(uri=file)
NameError: name 'Annotation' is not defined


Error in file: /home/matias/Documents/UdeSA/CNC/diariziation_error_rate/UCSF_manual_prepro/UCSF__33362_04-03-24__PictureDescription.txt
Traceback (most recent call last):
  File "/tmp/ipykernel_43805/769737209.py", line 17, in <module>
    annotation = Annotation(uri=file)
NameError: name 'Annotation' is not defined


Error in file: /home/matias/Documents/UdeSA/CNC/diariziation_error_rate/UCSF_manual_prepro/UCSF__33637_02-09-24__PictureDescription.txt
Traceback (most recent call last):
  File "/tmp/ipykernel_43805/769737209.py", line 17, in <module>
    annotation = Annotation(uri=file)
NameError: name 'Annotation' is not defined


Error in file: /home/matias/Documents/UdeSA/CNC/diariziation_error_rate/UCSF_manual_prepro/UCSF__34785_03-14-24__PictureDescription.txt
Traceback (most recent call last):
  File "/tmp/ipykernel_43805/769737209.py", line 17, in <module>
    annotation = Annotation(uri=file)
NameError: name 'Annotation' is not defined


Error in file: /home/matias/Documents/UdeSA/CNC/diariziation_error_rate/UCSF_manual_prepro/UCSF__24537_03-19-24__PictureDescription.txt
Traceback (most recent call last):
  File "/tmp/ipykernel_43805/769737209.py", line 17, in <module>
    annotation = Annotation(uri=file)
NameError: name 'Annotation' is not defined


Error in file: /home/matias/Documents/UdeSA/CNC/diariziation_error_rate/UCSF_manual_prepro/UCSF__35173_01-17-25__PictureDescription.txt
Traceback (most recent call last):
  File "/tmp/ipykernel_43805/769737209.py", line 17, in <module>
    annotation = Annotation(uri=file)
NameError: name 'Annotation' is not defined


Error in file: /home/matias/Documents/UdeSA/CNC/diariziation_error_rate/UCSF_manual_prepro/UCSF__8590_03-15-24__PictureDescription.txt
Traceback (most recent call last):
  File "/tmp/ipykernel_43805/769737209.py", line 17, in <module>
    annotation = Annotation(uri=file)
NameError: name 'Annotation' is not defined


Error in file: /home/matias/Documents/UdeSA/CNC/diariziation_error_rate/UCSF_manual_prepro/UCSF__33723_08-01-24__PictureDescription.txt
Traceback (most recent call last):
  File "/tmp/ipykernel_43805/769737209.py", line 17, in <module>
    annotation = Annotation(uri=file)
NameError: name 'Annotation' is not defined


Error in file: /home/matias/Documents/UdeSA/CNC/diariziation_error_rate/UCSF_manual_prepro/UCSF__24651_01-24-25__PictureDescription.txt
Traceback (most recent call last):
  File "/tmp/ipykernel_43805/769737209.py", line 17, in <module>
    annotation = Annotation(uri=file)
NameError: name 'Annotation' is not defined


Error in file: /home/matias/Documents/UdeSA/CNC/diariziation_error_rate/UCSF_manual_prepro/UCSF__34491_02-05-25__PictureDescription.txt
Traceback (most recent call last):
  File "/tmp/ipykernel_43805/769737209.py", line 17, in <module>
    annotation = Annotation(uri=file)
NameError: name 'Annotation' is not defined


Error in file: /home/matias/Documents/UdeSA/CNC/diariziation_error_rate/UCSF_manual_prepro/UCSF__6909_ 01-24-25__PictureDescription.txt
Traceback (most recent call last):
  File "/tmp/ipykernel_43805/769737209.py", line 17, in <module>
    annotation = Annotation(uri=file)
NameError: name 'Annotation' is not defined


Error in file: /home/matias/Documents/UdeSA/CNC/diariziation_error_rate/UCSF_manual_prepro/UCSF__34682_10-15-24__PictureDescription.txt
Traceback (most recent call last):
  File "/tmp/ipykernel_43805/769737209.py", line 17, in <module>
    annotation = Annotation(uri=file)
NameError: name 'Annotation' is not defined


Error in file: /home/matias/Documents/UdeSA/CNC/diariziation_error_rate/UCSF_manual_prepro/UCSF__34445_06-28-24__PictureDescription.txt
Traceback (most recent call last):
  File "/tmp/ipykernel_43805/769737209.py", line 17, in <module>
    annotation = Annotation(uri=file)
NameError: name 'Annotation' is not defined


Error in file: /home/matias/Documents/UdeSA/CNC/diariziation_error_rate/UCSF_manual_prepro/UCSF__33362_09-11-24__PictureDescription.txt
Traceback (most recent call last):
  File "/tmp/ipykernel_43805/769737209.py", line 17, in <module>
    annotation = Annotation(uri=file)
NameError: name 'Annotation' is not defined


Error in file: /home/matias/Documents/UdeSA/CNC/diariziation_error_rate/UCSF_manual_prepro/UCSF__34491_06-17-24__PictureDescription.txt
Traceback (most recent call last):
  File "/tmp/ipykernel_43805/769737209.py", line 17, in <module>
    annotation = Annotation(uri=file)
NameError: name 'Annotation' is not defined


Error in file: /home/matias/Documents/UdeSA/CNC/diariziation_error_rate/UCSF_manual_prepro/UCSF__24651_06-24-24__PictureDescription.txt
Traceback (most recent call last):
  File "/tmp/ipykernel_43805/769737209.py", line 17, in <module>
    annotation = Annotation(uri=file)
NameError: name 'Annotation' is not defined


Error in file: /home/matias/Documents/UdeSA/CNC/diariziation_error_rate/UCSF_manual_prepro/UCSF__7853_03-07-24__PictureDescription.txt
Traceback (most recent call last):
  File "/tmp/ipykernel_43805/769737209.py", line 17, in <module>
    annotation = Annotation(uri=file)
NameError: name 'Annotation' is not defined


Error in file: /home/matias/Documents/UdeSA/CNC/diariziation_error_rate/UCSF_manual_prepro/UCSF__35548_08-15-24__PictureDescription.txt
Traceback (most recent call last):
  File "/tmp/ipykernel_43805/769737209.py", line 17, in <module>
    annotation = Annotation(uri=file)
NameError: name 'Annotation' is not defined


Error in file: /home/matias/Documents/UdeSA/CNC/diariziation_error_rate/UCSF_manual_prepro/UCSF__8594_06-11-24__PictureDescription.txt
Traceback (most recent call last):
  File "/tmp/ipykernel_43805/769737209.py", line 17, in <module>
    annotation = Annotation(uri=file)
NameError: name 'Annotation' is not defined


Error in file: /home/matias/Documents/UdeSA/CNC/diariziation_error_rate/UCSF_manual_prepro/UCSF__6909_06-14-24__PictureDescription.txt
Traceback (most recent call last):
  File "/tmp/ipykernel_43805/769737209.py", line 17, in <module>
    annotation = Annotation(uri=file)
NameError: name 'Annotation' is not defined


Error in file: /home/matias/Documents/UdeSA/CNC/diariziation_error_rate/UCSF_manual_prepro/UCSF__33768_11-06-24__PictureDescription.txt
Traceback (most recent call last):
  File "/tmp/ipykernel_43805/769737209.py", line 17, in <module>
    annotation = Annotation(uri=file)
NameError: name 'Annotation' is not defined


Error in file: /home/matias/Documents/UdeSA/CNC/diariziation_error_rate/UCSF_manual_prepro/UCSF__33906_12-16-24__PictureDescription.txt
Traceback (most recent call last):
  File "/tmp/ipykernel_43805/769737209.py", line 17, in <module>
    annotation = Annotation(uri=file)
NameError: name 'Annotation' is not defined


Error in file: /home/matias/Documents/UdeSA/CNC/diariziation_error_rate/UCSF_manual_prepro/UCSF__35066_08-02-24__PictureDescription.txt
Traceback (most recent call last):
  File "/tmp/ipykernel_43805/769737209.py", line 17, in <module>
    annotation = Annotation(uri=file)
NameError: name 'Annotation' is not defined


Error in file: /home/matias/Documents/UdeSA/CNC/diariziation_error_rate/UCSF_manual_prepro/UCSF__35209_05-03-24__PictureDescription.txt
Traceback (most recent call last):
  File "/tmp/ipykernel_43805/769737209.py", line 17, in <module>
    annotation = Annotation(uri=file)
NameError: name 'Annotation' is not defined


Error in file: /home/matias/Documents/UdeSA/CNC/diariziation_error_rate/UCSF_manual_prepro/UCSF__33723_02-20-25__PictureDescription.txt
Traceback (most recent call last):
  File "/tmp/ipykernel_43805/769737209.py", line 17, in <module>
    annotation = Annotation(uri=file)
NameError: name 'Annotation' is not defined


Error in file: /home/matias/Documents/UdeSA/CNC/diariziation_error_rate/UCSF_manual_prepro/UCSF__33842_06-12-24__PictureDescription.txt
Traceback (most recent call last):
  File "/tmp/ipykernel_43805/769737209.py", line 17, in <module>
    annotation = Annotation(uri=file)
NameError: name 'Annotation' is not defined


Error in file: /home/matias/Documents/UdeSA/CNC/diariziation_error_rate/UCSF_manual_prepro/UCSF__34634_09-16-24__PictureDescription.txt
Traceback (most recent call last):
  File "/tmp/ipykernel_43805/769737209.py", line 17, in <module>
    annotation = Annotation(uri=file)
NameError: name 'Annotation' is not defined


Error in file: /home/matias/Documents/UdeSA/CNC/diariziation_error_rate/UCSF_manual_prepro/UCSF__33362_02-14-25__PictureDescription.txt
Traceback (most recent call last):
  File "/tmp/ipykernel_43805/769737209.py", line 29, in <module>
    hypothesis = txt2annotation(hypothesis_path, annotation)
  File "/tmp/ipykernel_43805/733004344.py", line 4, in txt2annotation
    with open(path_txt, 'r') as f:
  File "/home/matias/Documents/UdeSA/CNC/diariziation_error_rate/der_env/lib/python3.10/site-packages/IPython/core/interactiveshell.py", line 324, in _modified_open
    return io_open(file, *args, **kwargs)
FileNotFoundError: [Errno 2] No such file or directory: '/home/matias/Documents/UdeSA/CNC/diariziation_error_rate/UCSF_manual/UCSF__33362_02-14-25__PictureDescription.txt'


Error in file: /home/matias/Documents/UdeSA/CNC/diariziation_error_rate/UCSF_manual_prepro/UCSF__6909_ 01-24-25__PictureDescription.txt
Traceback (most recent call last):
  File "/tmp/ipykernel_43805/769737209.py", line 29, in <module>
    hypothesis = txt2annotation(hypothesis_path, annotation)
  File "/tmp/ipykernel_43805/733004344.py", line 4, in txt2annotation
    with open(path_txt, 'r') as f:
  File "/home/matias/Documents/UdeSA/CNC/diariziation_error_rate/der_env/lib/python3.10/site-packages/IPython/core/interactiveshell.py", line 324, in _modified_open
    return io_open(file, *args, **kwargs)
FileNotFoundError: [Errno 2] No such file or directory: '/home/matias/Documents/UdeSA/CNC/diariziation_error_rate/UCSF_manual/UCSF__6909_ 01-24-25__PictureDescription.txt'


Error in file: /home/matias/Documents/UdeSA/CNC/diariziation_error_rate/UCSF_manual_prepro/UCSF__12029_03-14-24__PictureDescription.txt
Traceback (most recent call last):
  File "/tmp/ipykernel_47045/769737209.py", line 17, in <module>
    annotation = Annotation(uri=file)
NameError: name 'Annotation' is not defined


Error in file: /home/matias/Documents/UdeSA/CNC/diariziation_error_rate/UCSF_manual_prepro/UCSF__35138_01-31-25__PictureDescription.txt
Traceback (most recent call last):
  File "/tmp/ipykernel_47045/769737209.py", line 17, in <module>
    annotation = Annotation(uri=file)
NameError: name 'Annotation' is not defined


Error in file: /home/matias/Documents/UdeSA/CNC/diariziation_error_rate/UCSF_manual_prepro/UCSF__35066_02-01-24__PictureDescription.txt
Traceback (most recent call last):
  File "/tmp/ipykernel_47045/769737209.py", line 17, in <module>
    annotation = Annotation(uri=file)
NameError: name 'Annotation' is not defined


Error in file: /home/matias/Documents/UdeSA/CNC/diariziation_error_rate/UCSF_manual_prepro/UCSF__33237_09-09-24__PictureDescription.txt
Traceback (most recent call last):
  File "/tmp/ipykernel_47045/769737209.py", line 17, in <module>
    annotation = Annotation(uri=file)
NameError: name 'Annotation' is not defined


Error in file: /home/matias/Documents/UdeSA/CNC/diariziation_error_rate/UCSF_manual_prepro/UCSF__33362_02-14-25__PictureDescription.txt
Traceback (most recent call last):
  File "/tmp/ipykernel_47045/769737209.py", line 17, in <module>
    annotation = Annotation(uri=file)
NameError: name 'Annotation' is not defined


Error in file: /home/matias/Documents/UdeSA/CNC/diariziation_error_rate/UCSF_manual_prepro/UCSF__35416_12-09-24__PictureDescription.txt
Traceback (most recent call last):
  File "/tmp/ipykernel_47045/769737209.py", line 17, in <module>
    annotation = Annotation(uri=file)
NameError: name 'Annotation' is not defined


Error in file: /home/matias/Documents/UdeSA/CNC/diariziation_error_rate/UCSF_manual_prepro/UCSF__33892_01-22-25__PictureDescription.txt
Traceback (most recent call last):
  File "/tmp/ipykernel_47045/769737209.py", line 17, in <module>
    annotation = Annotation(uri=file)
NameError: name 'Annotation' is not defined


Error in file: /home/matias/Documents/UdeSA/CNC/diariziation_error_rate/UCSF_manual_prepro/UCSF__34302_04-09-24__PictureDescription.txt
Traceback (most recent call last):
  File "/tmp/ipykernel_47045/769737209.py", line 17, in <module>
    annotation = Annotation(uri=file)
NameError: name 'Annotation' is not defined


Error in file: /home/matias/Documents/UdeSA/CNC/diariziation_error_rate/UCSF_manual_prepro/UCSF__33362_04-03-24__PictureDescription.txt
Traceback (most recent call last):
  File "/tmp/ipykernel_47045/769737209.py", line 17, in <module>
    annotation = Annotation(uri=file)
NameError: name 'Annotation' is not defined


Error in file: /home/matias/Documents/UdeSA/CNC/diariziation_error_rate/UCSF_manual_prepro/UCSF__33637_02-09-24__PictureDescription.txt
Traceback (most recent call last):
  File "/tmp/ipykernel_47045/769737209.py", line 17, in <module>
    annotation = Annotation(uri=file)
NameError: name 'Annotation' is not defined


Error in file: /home/matias/Documents/UdeSA/CNC/diariziation_error_rate/UCSF_manual_prepro/UCSF__34785_03-14-24__PictureDescription.txt
Traceback (most recent call last):
  File "/tmp/ipykernel_47045/769737209.py", line 17, in <module>
    annotation = Annotation(uri=file)
NameError: name 'Annotation' is not defined


Error in file: /home/matias/Documents/UdeSA/CNC/diariziation_error_rate/UCSF_manual_prepro/UCSF__24537_03-19-24__PictureDescription.txt
Traceback (most recent call last):
  File "/tmp/ipykernel_47045/769737209.py", line 17, in <module>
    annotation = Annotation(uri=file)
NameError: name 'Annotation' is not defined


Error in file: /home/matias/Documents/UdeSA/CNC/diariziation_error_rate/UCSF_manual_prepro/UCSF__35173_01-17-25__PictureDescription.txt
Traceback (most recent call last):
  File "/tmp/ipykernel_47045/769737209.py", line 17, in <module>
    annotation = Annotation(uri=file)
NameError: name 'Annotation' is not defined


Error in file: /home/matias/Documents/UdeSA/CNC/diariziation_error_rate/UCSF_manual_prepro/UCSF__8590_03-15-24__PictureDescription.txt
Traceback (most recent call last):
  File "/tmp/ipykernel_47045/769737209.py", line 17, in <module>
    annotation = Annotation(uri=file)
NameError: name 'Annotation' is not defined


Error in file: /home/matias/Documents/UdeSA/CNC/diariziation_error_rate/UCSF_manual_prepro/UCSF__33723_08-01-24__PictureDescription.txt
Traceback (most recent call last):
  File "/tmp/ipykernel_47045/769737209.py", line 17, in <module>
    annotation = Annotation(uri=file)
NameError: name 'Annotation' is not defined


Error in file: /home/matias/Documents/UdeSA/CNC/diariziation_error_rate/UCSF_manual_prepro/UCSF__24651_01-24-25__PictureDescription.txt
Traceback (most recent call last):
  File "/tmp/ipykernel_47045/769737209.py", line 17, in <module>
    annotation = Annotation(uri=file)
NameError: name 'Annotation' is not defined


Error in file: /home/matias/Documents/UdeSA/CNC/diariziation_error_rate/UCSF_manual_prepro/UCSF__34491_02-05-25__PictureDescription.txt
Traceback (most recent call last):
  File "/tmp/ipykernel_47045/769737209.py", line 17, in <module>
    annotation = Annotation(uri=file)
NameError: name 'Annotation' is not defined


Error in file: /home/matias/Documents/UdeSA/CNC/diariziation_error_rate/UCSF_manual_prepro/UCSF__6909_ 01-24-25__PictureDescription.txt
Traceback (most recent call last):
  File "/tmp/ipykernel_47045/769737209.py", line 17, in <module>
    annotation = Annotation(uri=file)
NameError: name 'Annotation' is not defined


Error in file: /home/matias/Documents/UdeSA/CNC/diariziation_error_rate/UCSF_manual_prepro/UCSF__34682_10-15-24__PictureDescription.txt
Traceback (most recent call last):
  File "/tmp/ipykernel_47045/769737209.py", line 17, in <module>
    annotation = Annotation(uri=file)
NameError: name 'Annotation' is not defined


Error in file: /home/matias/Documents/UdeSA/CNC/diariziation_error_rate/UCSF_manual_prepro/UCSF__34445_06-28-24__PictureDescription.txt
Traceback (most recent call last):
  File "/tmp/ipykernel_47045/769737209.py", line 17, in <module>
    annotation = Annotation(uri=file)
NameError: name 'Annotation' is not defined


Error in file: /home/matias/Documents/UdeSA/CNC/diariziation_error_rate/UCSF_manual_prepro/UCSF__33362_09-11-24__PictureDescription.txt
Traceback (most recent call last):
  File "/tmp/ipykernel_47045/769737209.py", line 17, in <module>
    annotation = Annotation(uri=file)
NameError: name 'Annotation' is not defined


Error in file: /home/matias/Documents/UdeSA/CNC/diariziation_error_rate/UCSF_manual_prepro/UCSF__34491_06-17-24__PictureDescription.txt
Traceback (most recent call last):
  File "/tmp/ipykernel_47045/769737209.py", line 17, in <module>
    annotation = Annotation(uri=file)
NameError: name 'Annotation' is not defined


Error in file: /home/matias/Documents/UdeSA/CNC/diariziation_error_rate/UCSF_manual_prepro/UCSF__24651_06-24-24__PictureDescription.txt
Traceback (most recent call last):
  File "/tmp/ipykernel_47045/769737209.py", line 17, in <module>
    annotation = Annotation(uri=file)
NameError: name 'Annotation' is not defined


Error in file: /home/matias/Documents/UdeSA/CNC/diariziation_error_rate/UCSF_manual_prepro/UCSF__7853_03-07-24__PictureDescription.txt
Traceback (most recent call last):
  File "/tmp/ipykernel_47045/769737209.py", line 17, in <module>
    annotation = Annotation(uri=file)
NameError: name 'Annotation' is not defined


Error in file: /home/matias/Documents/UdeSA/CNC/diariziation_error_rate/UCSF_manual_prepro/UCSF__35548_08-15-24__PictureDescription.txt
Traceback (most recent call last):
  File "/tmp/ipykernel_47045/769737209.py", line 17, in <module>
    annotation = Annotation(uri=file)
NameError: name 'Annotation' is not defined


Error in file: /home/matias/Documents/UdeSA/CNC/diariziation_error_rate/UCSF_manual_prepro/UCSF__8594_06-11-24__PictureDescription.txt
Traceback (most recent call last):
  File "/tmp/ipykernel_47045/769737209.py", line 17, in <module>
    annotation = Annotation(uri=file)
NameError: name 'Annotation' is not defined


Error in file: /home/matias/Documents/UdeSA/CNC/diariziation_error_rate/UCSF_manual_prepro/UCSF__6909_06-14-24__PictureDescription.txt
Traceback (most recent call last):
  File "/tmp/ipykernel_47045/769737209.py", line 17, in <module>
    annotation = Annotation(uri=file)
NameError: name 'Annotation' is not defined


Error in file: /home/matias/Documents/UdeSA/CNC/diariziation_error_rate/UCSF_manual_prepro/UCSF__33768_11-06-24__PictureDescription.txt
Traceback (most recent call last):
  File "/tmp/ipykernel_47045/769737209.py", line 17, in <module>
    annotation = Annotation(uri=file)
NameError: name 'Annotation' is not defined


Error in file: /home/matias/Documents/UdeSA/CNC/diariziation_error_rate/UCSF_manual_prepro/UCSF__33906_12-16-24__PictureDescription.txt
Traceback (most recent call last):
  File "/tmp/ipykernel_47045/769737209.py", line 17, in <module>
    annotation = Annotation(uri=file)
NameError: name 'Annotation' is not defined


Error in file: /home/matias/Documents/UdeSA/CNC/diariziation_error_rate/UCSF_manual_prepro/UCSF__35066_08-02-24__PictureDescription.txt
Traceback (most recent call last):
  File "/tmp/ipykernel_47045/769737209.py", line 17, in <module>
    annotation = Annotation(uri=file)
NameError: name 'Annotation' is not defined


Error in file: /home/matias/Documents/UdeSA/CNC/diariziation_error_rate/UCSF_manual_prepro/UCSF__35209_05-03-24__PictureDescription.txt
Traceback (most recent call last):
  File "/tmp/ipykernel_47045/769737209.py", line 17, in <module>
    annotation = Annotation(uri=file)
NameError: name 'Annotation' is not defined


Error in file: /home/matias/Documents/UdeSA/CNC/diariziation_error_rate/UCSF_manual_prepro/UCSF__33723_02-20-25__PictureDescription.txt
Traceback (most recent call last):
  File "/tmp/ipykernel_47045/769737209.py", line 17, in <module>
    annotation = Annotation(uri=file)
NameError: name 'Annotation' is not defined


Error in file: /home/matias/Documents/UdeSA/CNC/diariziation_error_rate/UCSF_manual_prepro/UCSF__33842_06-12-24__PictureDescription.txt
Traceback (most recent call last):
  File "/tmp/ipykernel_47045/769737209.py", line 17, in <module>
    annotation = Annotation(uri=file)
NameError: name 'Annotation' is not defined


Error in file: /home/matias/Documents/UdeSA/CNC/diariziation_error_rate/UCSF_manual_prepro/UCSF__34634_09-16-24__PictureDescription.txt
Traceback (most recent call last):
  File "/tmp/ipykernel_47045/769737209.py", line 17, in <module>
    annotation = Annotation(uri=file)
NameError: name 'Annotation' is not defined


Error in file: /home/matias/Documents/UdeSA/CNC/diariziation_error_rate/UCSF_manual_prepro/UCSF__33362_02-14-25__PictureDescription.txt
Traceback (most recent call last):
  File "/tmp/ipykernel_47045/769737209.py", line 29, in <module>
    hypothesis = txt2annotation(hypothesis_path, annotation)
  File "/tmp/ipykernel_47045/733004344.py", line 4, in txt2annotation
    with open(path_txt, 'r') as f:
  File "/home/matias/Documents/UdeSA/CNC/diariziation_error_rate/der_env/lib/python3.10/site-packages/IPython/core/interactiveshell.py", line 324, in _modified_open
    return io_open(file, *args, **kwargs)
FileNotFoundError: [Errno 2] No such file or directory: '/home/matias/Documents/UdeSA/CNC/diariziation_error_rate/UCSF_manual/UCSF__33362_02-14-25__PictureDescription.txt'


Error in file: /home/matias/Documents/UdeSA/CNC/diariziation_error_rate/UCSF_manual_prepro/UCSF__34491_02-05-25__PictureDescription.txt
Traceback (most recent call last):
  File "/tmp/ipykernel_47045/769737209.py", line 29, in <module>
    hypothesis = txt2annotation(hypothesis_path, annotation)
  File "/tmp/ipykernel_47045/733004344.py", line 4, in txt2annotation
    with open(path_txt, 'r') as f:
  File "/home/matias/Documents/UdeSA/CNC/diariziation_error_rate/der_env/lib/python3.10/site-packages/IPython/core/interactiveshell.py", line 324, in _modified_open
    return io_open(file, *args, **kwargs)
FileNotFoundError: [Errno 2] No such file or directory: '/home/matias/Documents/UdeSA/CNC/diariziation_error_rate/UCSF_manual/UCSF__34491_02-05-25__PictureDescription.txt'


Error in file: /home/matias/Documents/UdeSA/CNC/diariziation_error_rate/UCSF_manual_prepro/UCSF__6909_ 01-24-25__PictureDescription.txt
Traceback (most recent call last):
  File "/tmp/ipykernel_47045/769737209.py", line 29, in <module>
    hypothesis = txt2annotation(hypothesis_path, annotation)
  File "/tmp/ipykernel_47045/733004344.py", line 4, in txt2annotation
    with open(path_txt, 'r') as f:
  File "/home/matias/Documents/UdeSA/CNC/diariziation_error_rate/der_env/lib/python3.10/site-packages/IPython/core/interactiveshell.py", line 324, in _modified_open
    return io_open(file, *args, **kwargs)
FileNotFoundError: [Errno 2] No such file or directory: '/home/matias/Documents/UdeSA/CNC/diariziation_error_rate/UCSF_manual/UCSF__6909_ 01-24-25__PictureDescription.txt'


Error in file: /home/matias/Documents/UdeSA/CNC/diariziation_error_rate/UCSF_manual_prepro/UCSF__33842_06-12-24__PictureDescription.txt
Traceback (most recent call last):
  File "/tmp/ipykernel_47045/769737209.py", line 29, in <module>
    hypothesis = txt2annotation(hypothesis_path, annotation)
  File "/tmp/ipykernel_47045/733004344.py", line 4, in txt2annotation
    with open(path_txt, 'r') as f:
  File "/home/matias/Documents/UdeSA/CNC/diariziation_error_rate/der_env/lib/python3.10/site-packages/IPython/core/interactiveshell.py", line 324, in _modified_open
    return io_open(file, *args, **kwargs)
FileNotFoundError: [Errno 2] No such file or directory: '/home/matias/Documents/UdeSA/CNC/diariziation_error_rate/UCSF_manual/UCSF__33842_06-12-24__PictureDescription.txt'


Error in file: /home/matias/Documents/UdeSA/CNC/diariziation_error_rate/GENFI_Error_Rates/DER-ground-truth/Miguel/17-039_FREE.txt
Traceback (most recent call last):
  File "/tmp/ipykernel_6572/3471649027.py", line 29, in <module>
    hypothesis = txt2annotation(hypothesis_path, annotation)
  File "/tmp/ipykernel_6572/733004344.py", line 4, in txt2annotation
    with open(path_txt, 'r') as f:
  File "/home/matias/Documents/UdeSA/CNC/diariziation_error_rate/der_env/lib/python3.10/site-packages/IPython/core/interactiveshell.py", line 324, in _modified_open
    return io_open(file, *args, **kwargs)
FileNotFoundError: [Errno 2] No such file or directory: '/home/matias/Documents/UdeSA/CNC/diariziation_error_rate/GENFI_Error_Rates/DER-predictions/Miguel/17-039_FREE.txt'


Error in file: /home/matias/Documents/UdeSA/CNC/diariziation_error_rate/GENFI_Error_Rates/DER-ground-truth/Miguel/17-026_FREE.txt
Traceback (most recent call last):
  File "/tmp/ipykernel_6572/3471649027.py", line 29, in <module>
    hypothesis = txt2annotation(hypothesis_path, annotation)
  File "/tmp/ipykernel_6572/733004344.py", line 4, in txt2annotation
    with open(path_txt, 'r') as f:
  File "/home/matias/Documents/UdeSA/CNC/diariziation_error_rate/der_env/lib/python3.10/site-packages/IPython/core/interactiveshell.py", line 324, in _modified_open
    return io_open(file, *args, **kwargs)
FileNotFoundError: [Errno 2] No such file or directory: '/home/matias/Documents/UdeSA/CNC/diariziation_error_rate/GENFI_Error_Rates/DER-predictions/Miguel/17-026_FREE.txt'


Error in file: /home/matias/Documents/UdeSA/CNC/diariziation_error_rate/GENFI_Error_Rates/DER-ground-truth/Miguel/02-074_FREE.txt
Traceback (most recent call last):
  File "/tmp/ipykernel_6572/3471649027.py", line 29, in <module>
    hypothesis = txt2annotation(hypothesis_path, annotation)
  File "/tmp/ipykernel_6572/733004344.py", line 4, in txt2annotation
    with open(path_txt, 'r') as f:
  File "/home/matias/Documents/UdeSA/CNC/diariziation_error_rate/der_env/lib/python3.10/site-packages/IPython/core/interactiveshell.py", line 324, in _modified_open
    return io_open(file, *args, **kwargs)
FileNotFoundError: [Errno 2] No such file or directory: '/home/matias/Documents/UdeSA/CNC/diariziation_error_rate/GENFI_Error_Rates/DER-predictions/Miguel/02-074_FREE.txt'


Error in file: /home/matias/Documents/UdeSA/CNC/diariziation_error_rate/GENFI_Error_Rates/DER-ground-truth/Miguel/01-092_FREE.txt
Traceback (most recent call last):
  File "/tmp/ipykernel_6572/3471649027.py", line 29, in <module>
    hypothesis = txt2annotation(hypothesis_path, annotation)
  File "/tmp/ipykernel_6572/733004344.py", line 4, in txt2annotation
    with open(path_txt, 'r') as f:
  File "/home/matias/Documents/UdeSA/CNC/diariziation_error_rate/der_env/lib/python3.10/site-packages/IPython/core/interactiveshell.py", line 324, in _modified_open
    return io_open(file, *args, **kwargs)
FileNotFoundError: [Errno 2] No such file or directory: '/home/matias/Documents/UdeSA/CNC/diariziation_error_rate/GENFI_Error_Rates/DER-predictions/Miguel/01-092_FREE.txt'


Error in file: /home/matias/Documents/UdeSA/CNC/diariziation_error_rate/GENFI_Error_Rates/DER-ground-truth/Miguel/02-060_FREE.txt
Traceback (most recent call last):
  File "/tmp/ipykernel_6572/3471649027.py", line 29, in <module>
    hypothesis = txt2annotation(hypothesis_path, annotation)
  File "/tmp/ipykernel_6572/733004344.py", line 4, in txt2annotation
    with open(path_txt, 'r') as f:
  File "/home/matias/Documents/UdeSA/CNC/diariziation_error_rate/der_env/lib/python3.10/site-packages/IPython/core/interactiveshell.py", line 324, in _modified_open
    return io_open(file, *args, **kwargs)
FileNotFoundError: [Errno 2] No such file or directory: '/home/matias/Documents/UdeSA/CNC/diariziation_error_rate/GENFI_Error_Rates/DER-predictions/Miguel/02-060_FREE.txt'


Error in file: /home/matias/Documents/UdeSA/CNC/diariziation_error_rate/GENFI_Error_Rates/DER-ground-truth/Miguel/07-034_FREE.txt
Traceback (most recent call last):
  File "/tmp/ipykernel_6572/3471649027.py", line 29, in <module>
    hypothesis = txt2annotation(hypothesis_path, annotation)
  File "/tmp/ipykernel_6572/733004344.py", line 4, in txt2annotation
    with open(path_txt, 'r') as f:
  File "/home/matias/Documents/UdeSA/CNC/diariziation_error_rate/der_env/lib/python3.10/site-packages/IPython/core/interactiveshell.py", line 324, in _modified_open
    return io_open(file, *args, **kwargs)
FileNotFoundError: [Errno 2] No such file or directory: '/home/matias/Documents/UdeSA/CNC/diariziation_error_rate/GENFI_Error_Rates/DER-predictions/Miguel/07-034_FREE.txt'


Error in file: /home/matias/Documents/UdeSA/CNC/diariziation_error_rate/GENFI_Error_Rates/DER-ground-truth/Miguel/17-018_FREE.txt
Traceback (most recent call last):
  File "/tmp/ipykernel_6572/3471649027.py", line 29, in <module>
    hypothesis = txt2annotation(hypothesis_path, annotation)
  File "/tmp/ipykernel_6572/733004344.py", line 4, in txt2annotation
    with open(path_txt, 'r') as f:
  File "/home/matias/Documents/UdeSA/CNC/diariziation_error_rate/der_env/lib/python3.10/site-packages/IPython/core/interactiveshell.py", line 324, in _modified_open
    return io_open(file, *args, **kwargs)
FileNotFoundError: [Errno 2] No such file or directory: '/home/matias/Documents/UdeSA/CNC/diariziation_error_rate/GENFI_Error_Rates/DER-predictions/Miguel/17-018_FREE.txt'


Error in file: /home/matias/Documents/UdeSA/CNC/diariziation_error_rate/GENFI_Error_Rates/DER-ground-truth/Rafa/01-076__FREE.txt
Traceback (most recent call last):
  File "/tmp/ipykernel_6572/3471649027.py", line 29, in <module>
    hypothesis = txt2annotation(hypothesis_path, annotation)
  File "/tmp/ipykernel_6572/733004344.py", line 4, in txt2annotation
    with open(path_txt, 'r') as f:
  File "/home/matias/Documents/UdeSA/CNC/diariziation_error_rate/der_env/lib/python3.10/site-packages/IPython/core/interactiveshell.py", line 324, in _modified_open
    return io_open(file, *args, **kwargs)
FileNotFoundError: [Errno 2] No such file or directory: '/home/matias/Documents/UdeSA/CNC/diariziation_error_rate/GENFI_Error_Rates/DER-predictions/Rafa/01-076__FREE.txt'


Error in file: /home/matias/Documents/UdeSA/CNC/diariziation_error_rate/GENFI_Error_Rates/DER-ground-truth/Rafa/15-064__FREE.txt
Traceback (most recent call last):
  File "/tmp/ipykernel_6572/3471649027.py", line 29, in <module>
    hypothesis = txt2annotation(hypothesis_path, annotation)
  File "/tmp/ipykernel_6572/733004344.py", line 4, in txt2annotation
    with open(path_txt, 'r') as f:
  File "/home/matias/Documents/UdeSA/CNC/diariziation_error_rate/der_env/lib/python3.10/site-packages/IPython/core/interactiveshell.py", line 324, in _modified_open
    return io_open(file, *args, **kwargs)
FileNotFoundError: [Errno 2] No such file or directory: '/home/matias/Documents/UdeSA/CNC/diariziation_error_rate/GENFI_Error_Rates/DER-predictions/Rafa/15-064__FREE.txt'


Error in file: /home/matias/Documents/UdeSA/CNC/diariziation_error_rate/GENFI_Error_Rates/DER-ground-truth/Rafa/17-029__FREE.txt
Traceback (most recent call last):
  File "/tmp/ipykernel_6572/3471649027.py", line 29, in <module>
    hypothesis = txt2annotation(hypothesis_path, annotation)
  File "/tmp/ipykernel_6572/733004344.py", line 4, in txt2annotation
    with open(path_txt, 'r') as f:
  File "/home/matias/Documents/UdeSA/CNC/diariziation_error_rate/der_env/lib/python3.10/site-packages/IPython/core/interactiveshell.py", line 324, in _modified_open
    return io_open(file, *args, **kwargs)
FileNotFoundError: [Errno 2] No such file or directory: '/home/matias/Documents/UdeSA/CNC/diariziation_error_rate/GENFI_Error_Rates/DER-predictions/Rafa/17-029__FREE.txt'


Error in file: /home/matias/Documents/UdeSA/CNC/diariziation_error_rate/GENFI_Error_Rates/DER-ground-truth/Rafa/01-158__FREE.txt
Traceback (most recent call last):
  File "/tmp/ipykernel_6572/3471649027.py", line 29, in <module>
    hypothesis = txt2annotation(hypothesis_path, annotation)
  File "/tmp/ipykernel_6572/733004344.py", line 4, in txt2annotation
    with open(path_txt, 'r') as f:
  File "/home/matias/Documents/UdeSA/CNC/diariziation_error_rate/der_env/lib/python3.10/site-packages/IPython/core/interactiveshell.py", line 324, in _modified_open
    return io_open(file, *args, **kwargs)
FileNotFoundError: [Errno 2] No such file or directory: '/home/matias/Documents/UdeSA/CNC/diariziation_error_rate/GENFI_Error_Rates/DER-predictions/Rafa/01-158__FREE.txt'


Error in file: /home/matias/Documents/UdeSA/CNC/diariziation_error_rate/GENFI_Error_Rates/DER-ground-truth/Rafa/01-182__FREE.txt
Traceback (most recent call last):
  File "/tmp/ipykernel_6572/3471649027.py", line 29, in <module>
    hypothesis = txt2annotation(hypothesis_path, annotation)
  File "/tmp/ipykernel_6572/733004344.py", line 4, in txt2annotation
    with open(path_txt, 'r') as f:
  File "/home/matias/Documents/UdeSA/CNC/diariziation_error_rate/der_env/lib/python3.10/site-packages/IPython/core/interactiveshell.py", line 324, in _modified_open
    return io_open(file, *args, **kwargs)
FileNotFoundError: [Errno 2] No such file or directory: '/home/matias/Documents/UdeSA/CNC/diariziation_error_rate/GENFI_Error_Rates/DER-predictions/Rafa/01-182__FREE.txt'


Error in file: /home/matias/Documents/UdeSA/CNC/diariziation_error_rate/GENFI_Error_Rates/DER-ground-truth/Rafa/15-091__FREE.txt
Traceback (most recent call last):
  File "/tmp/ipykernel_6572/3471649027.py", line 29, in <module>
    hypothesis = txt2annotation(hypothesis_path, annotation)
  File "/tmp/ipykernel_6572/733004344.py", line 4, in txt2annotation
    with open(path_txt, 'r') as f:
  File "/home/matias/Documents/UdeSA/CNC/diariziation_error_rate/der_env/lib/python3.10/site-packages/IPython/core/interactiveshell.py", line 324, in _modified_open
    return io_open(file, *args, **kwargs)
FileNotFoundError: [Errno 2] No such file or directory: '/home/matias/Documents/UdeSA/CNC/diariziation_error_rate/GENFI_Error_Rates/DER-predictions/Rafa/15-091__FREE.txt'


Error in file: /home/matias/Documents/UdeSA/CNC/diariziation_error_rate/GENFI_Error_Rates/DER-ground-truth/Rafa/01-121__FREE.txt
Traceback (most recent call last):
  File "/tmp/ipykernel_6572/3471649027.py", line 29, in <module>
    hypothesis = txt2annotation(hypothesis_path, annotation)
  File "/tmp/ipykernel_6572/733004344.py", line 4, in txt2annotation
    with open(path_txt, 'r') as f:
  File "/home/matias/Documents/UdeSA/CNC/diariziation_error_rate/der_env/lib/python3.10/site-packages/IPython/core/interactiveshell.py", line 324, in _modified_open
    return io_open(file, *args, **kwargs)
FileNotFoundError: [Errno 2] No such file or directory: '/home/matias/Documents/UdeSA/CNC/diariziation_error_rate/GENFI_Error_Rates/DER-predictions/Rafa/01-121__FREE.txt'


Error in file: /home/matias/Documents/UdeSA/CNC/diariziation_error_rate/GENFI_Error_Rates/DER-ground-truth/Rafa/15-040__FREE.txt
Traceback (most recent call last):
  File "/tmp/ipykernel_6572/3471649027.py", line 29, in <module>
    hypothesis = txt2annotation(hypothesis_path, annotation)
  File "/tmp/ipykernel_6572/733004344.py", line 4, in txt2annotation
    with open(path_txt, 'r') as f:
  File "/home/matias/Documents/UdeSA/CNC/diariziation_error_rate/der_env/lib/python3.10/site-packages/IPython/core/interactiveshell.py", line 324, in _modified_open
    return io_open(file, *args, **kwargs)
FileNotFoundError: [Errno 2] No such file or directory: '/home/matias/Documents/UdeSA/CNC/diariziation_error_rate/GENFI_Error_Rates/DER-predictions/Rafa/15-040__FREE.txt'


Error in file: /home/matias/Documents/UdeSA/CNC/diariziation_error_rate/GENFI_Error_Rates/DER-ground-truth/Rafa/02-006__FREE.txt
Traceback (most recent call last):
  File "/tmp/ipykernel_6572/3471649027.py", line 29, in <module>
    hypothesis = txt2annotation(hypothesis_path, annotation)
  File "/tmp/ipykernel_6572/733004344.py", line 4, in txt2annotation
    with open(path_txt, 'r') as f:
  File "/home/matias/Documents/UdeSA/CNC/diariziation_error_rate/der_env/lib/python3.10/site-packages/IPython/core/interactiveshell.py", line 324, in _modified_open
    return io_open(file, *args, **kwargs)
FileNotFoundError: [Errno 2] No such file or directory: '/home/matias/Documents/UdeSA/CNC/diariziation_error_rate/GENFI_Error_Rates/DER-predictions/Rafa/02-006__FREE.txt'


Error in file: /home/matias/Documents/UdeSA/CNC/diariziation_error_rate/GENFI_Error_Rates/DER-ground-truth/Vanesa/01-153__FREE.txt
Traceback (most recent call last):
  File "/tmp/ipykernel_6572/3471649027.py", line 29, in <module>
    hypothesis = txt2annotation(hypothesis_path, annotation)
  File "/tmp/ipykernel_6572/733004344.py", line 4, in txt2annotation
    with open(path_txt, 'r') as f:
  File "/home/matias/Documents/UdeSA/CNC/diariziation_error_rate/der_env/lib/python3.10/site-packages/IPython/core/interactiveshell.py", line 324, in _modified_open
    return io_open(file, *args, **kwargs)
FileNotFoundError: [Errno 2] No such file or directory: '/home/matias/Documents/UdeSA/CNC/diariziation_error_rate/GENFI_Error_Rates/DER-predictions/Vanesa/01-153__FREE.txt'


Error in file: /home/matias/Documents/UdeSA/CNC/diariziation_error_rate/GENFI_Error_Rates/DER-ground-truth/Vanesa/17-013__FREE.txt
Traceback (most recent call last):
  File "/tmp/ipykernel_6572/3471649027.py", line 29, in <module>
    hypothesis = txt2annotation(hypothesis_path, annotation)
  File "/tmp/ipykernel_6572/733004344.py", line 4, in txt2annotation
    with open(path_txt, 'r') as f:
  File "/home/matias/Documents/UdeSA/CNC/diariziation_error_rate/der_env/lib/python3.10/site-packages/IPython/core/interactiveshell.py", line 324, in _modified_open
    return io_open(file, *args, **kwargs)
FileNotFoundError: [Errno 2] No such file or directory: '/home/matias/Documents/UdeSA/CNC/diariziation_error_rate/GENFI_Error_Rates/DER-predictions/Vanesa/17-013__FREE.txt'


Error in file: /home/matias/Documents/UdeSA/CNC/diariziation_error_rate/GENFI_Error_Rates/DER-ground-truth/Vanesa/01-112__FREE.txt
Traceback (most recent call last):
  File "/tmp/ipykernel_6572/3471649027.py", line 29, in <module>
    hypothesis = txt2annotation(hypothesis_path, annotation)
  File "/tmp/ipykernel_6572/733004344.py", line 4, in txt2annotation
    with open(path_txt, 'r') as f:
  File "/home/matias/Documents/UdeSA/CNC/diariziation_error_rate/der_env/lib/python3.10/site-packages/IPython/core/interactiveshell.py", line 324, in _modified_open
    return io_open(file, *args, **kwargs)
FileNotFoundError: [Errno 2] No such file or directory: '/home/matias/Documents/UdeSA/CNC/diariziation_error_rate/GENFI_Error_Rates/DER-predictions/Vanesa/01-112__FREE.txt'


Error in file: /home/matias/Documents/UdeSA/CNC/diariziation_error_rate/GENFI_Error_Rates/DER-ground-truth/Vanesa/01-143__FREE.txt
Traceback (most recent call last):
  File "/tmp/ipykernel_6572/3471649027.py", line 29, in <module>
    hypothesis = txt2annotation(hypothesis_path, annotation)
  File "/tmp/ipykernel_6572/733004344.py", line 4, in txt2annotation
    with open(path_txt, 'r') as f:
  File "/home/matias/Documents/UdeSA/CNC/diariziation_error_rate/der_env/lib/python3.10/site-packages/IPython/core/interactiveshell.py", line 324, in _modified_open
    return io_open(file, *args, **kwargs)
FileNotFoundError: [Errno 2] No such file or directory: '/home/matias/Documents/UdeSA/CNC/diariziation_error_rate/GENFI_Error_Rates/DER-predictions/Vanesa/01-143__FREE.txt'


Error in file: /home/matias/Documents/UdeSA/CNC/diariziation_error_rate/GENFI_Error_Rates/DER-ground-truth/Vanesa/07-013__FREE.txt
Traceback (most recent call last):
  File "/tmp/ipykernel_6572/3471649027.py", line 29, in <module>
    hypothesis = txt2annotation(hypothesis_path, annotation)
  File "/tmp/ipykernel_6572/733004344.py", line 4, in txt2annotation
    with open(path_txt, 'r') as f:
  File "/home/matias/Documents/UdeSA/CNC/diariziation_error_rate/der_env/lib/python3.10/site-packages/IPython/core/interactiveshell.py", line 324, in _modified_open
    return io_open(file, *args, **kwargs)
FileNotFoundError: [Errno 2] No such file or directory: '/home/matias/Documents/UdeSA/CNC/diariziation_error_rate/GENFI_Error_Rates/DER-predictions/Vanesa/07-013__FREE.txt'


Error in file: /home/matias/Documents/UdeSA/CNC/diariziation_error_rate/GENFI_Error_Rates/DER-ground-truth/Vanesa/15-073__FREE.txt
Traceback (most recent call last):
  File "/tmp/ipykernel_6572/3471649027.py", line 29, in <module>
    hypothesis = txt2annotation(hypothesis_path, annotation)
  File "/tmp/ipykernel_6572/733004344.py", line 4, in txt2annotation
    with open(path_txt, 'r') as f:
  File "/home/matias/Documents/UdeSA/CNC/diariziation_error_rate/der_env/lib/python3.10/site-packages/IPython/core/interactiveshell.py", line 324, in _modified_open
    return io_open(file, *args, **kwargs)
FileNotFoundError: [Errno 2] No such file or directory: '/home/matias/Documents/UdeSA/CNC/diariziation_error_rate/GENFI_Error_Rates/DER-predictions/Vanesa/15-073__FREE.txt'


Error in file: /home/matias/Documents/UdeSA/CNC/diariziation_error_rate/GENFI_Error_Rates/DER-ground-truth/Vanesa/01-127__FREE.txt
Traceback (most recent call last):
  File "/tmp/ipykernel_6572/3471649027.py", line 29, in <module>
    hypothesis = txt2annotation(hypothesis_path, annotation)
  File "/tmp/ipykernel_6572/733004344.py", line 4, in txt2annotation
    with open(path_txt, 'r') as f:
  File "/home/matias/Documents/UdeSA/CNC/diariziation_error_rate/der_env/lib/python3.10/site-packages/IPython/core/interactiveshell.py", line 324, in _modified_open
    return io_open(file, *args, **kwargs)
FileNotFoundError: [Errno 2] No such file or directory: '/home/matias/Documents/UdeSA/CNC/diariziation_error_rate/GENFI_Error_Rates/DER-predictions/Vanesa/01-127__FREE.txt'


Error in file: /home/matias/Documents/UdeSA/CNC/diariziation_error_rate/GENFI_Error_Rates/DER-ground-truth/Vanesa/15-084__FREE.txt
Traceback (most recent call last):
  File "/tmp/ipykernel_6572/3471649027.py", line 29, in <module>
    hypothesis = txt2annotation(hypothesis_path, annotation)
  File "/tmp/ipykernel_6572/733004344.py", line 4, in txt2annotation
    with open(path_txt, 'r') as f:
  File "/home/matias/Documents/UdeSA/CNC/diariziation_error_rate/der_env/lib/python3.10/site-packages/IPython/core/interactiveshell.py", line 324, in _modified_open
    return io_open(file, *args, **kwargs)
FileNotFoundError: [Errno 2] No such file or directory: '/home/matias/Documents/UdeSA/CNC/diariziation_error_rate/GENFI_Error_Rates/DER-predictions/Vanesa/15-084__FREE.txt'


Error in file: /home/matias/Documents/UdeSA/CNC/diariziation_error_rate/GENFI_Error_Rates/DER-ground-truth/Agus/07-037__FREE.txt
Traceback (most recent call last):
  File "/tmp/ipykernel_6572/3471649027.py", line 29, in <module>
    hypothesis = txt2annotation(hypothesis_path, annotation)
  File "/tmp/ipykernel_6572/733004344.py", line 4, in txt2annotation
    with open(path_txt, 'r') as f:
  File "/home/matias/Documents/UdeSA/CNC/diariziation_error_rate/der_env/lib/python3.10/site-packages/IPython/core/interactiveshell.py", line 324, in _modified_open
    return io_open(file, *args, **kwargs)
FileNotFoundError: [Errno 2] No such file or directory: '/home/matias/Documents/UdeSA/CNC/diariziation_error_rate/GENFI_Error_Rates/DER-predictions/Agus/07-037__FREE.txt'


Error in file: /home/matias/Documents/UdeSA/CNC/diariziation_error_rate/GENFI_Error_Rates/DER-ground-truth/Agus/01-169__FREE.txt
Traceback (most recent call last):
  File "/tmp/ipykernel_6572/3471649027.py", line 29, in <module>
    hypothesis = txt2annotation(hypothesis_path, annotation)
  File "/tmp/ipykernel_6572/733004344.py", line 4, in txt2annotation
    with open(path_txt, 'r') as f:
  File "/home/matias/Documents/UdeSA/CNC/diariziation_error_rate/der_env/lib/python3.10/site-packages/IPython/core/interactiveshell.py", line 324, in _modified_open
    return io_open(file, *args, **kwargs)
FileNotFoundError: [Errno 2] No such file or directory: '/home/matias/Documents/UdeSA/CNC/diariziation_error_rate/GENFI_Error_Rates/DER-predictions/Agus/01-169__FREE.txt'


Error in file: /home/matias/Documents/UdeSA/CNC/diariziation_error_rate/GENFI_Error_Rates/DER-ground-truth/Agus/15-014__FREE.txt
Traceback (most recent call last):
  File "/tmp/ipykernel_6572/3471649027.py", line 29, in <module>
    hypothesis = txt2annotation(hypothesis_path, annotation)
  File "/tmp/ipykernel_6572/733004344.py", line 4, in txt2annotation
    with open(path_txt, 'r') as f:
  File "/home/matias/Documents/UdeSA/CNC/diariziation_error_rate/der_env/lib/python3.10/site-packages/IPython/core/interactiveshell.py", line 324, in _modified_open
    return io_open(file, *args, **kwargs)
FileNotFoundError: [Errno 2] No such file or directory: '/home/matias/Documents/UdeSA/CNC/diariziation_error_rate/GENFI_Error_Rates/DER-predictions/Agus/15-014__FREE.txt'


Error in file: /home/matias/Documents/UdeSA/CNC/diariziation_error_rate/GENFI_Error_Rates/DER-ground-truth/Agus/17-027__FREE.txt
Traceback (most recent call last):
  File "/tmp/ipykernel_6572/3471649027.py", line 29, in <module>
    hypothesis = txt2annotation(hypothesis_path, annotation)
  File "/tmp/ipykernel_6572/733004344.py", line 4, in txt2annotation
    with open(path_txt, 'r') as f:
  File "/home/matias/Documents/UdeSA/CNC/diariziation_error_rate/der_env/lib/python3.10/site-packages/IPython/core/interactiveshell.py", line 324, in _modified_open
    return io_open(file, *args, **kwargs)
FileNotFoundError: [Errno 2] No such file or directory: '/home/matias/Documents/UdeSA/CNC/diariziation_error_rate/GENFI_Error_Rates/DER-predictions/Agus/17-027__FREE.txt'


Error in file: /home/matias/Documents/UdeSA/CNC/diariziation_error_rate/GENFI_Error_Rates/DER-ground-truth/Agus/07-047__FREE.txt
Traceback (most recent call last):
  File "/tmp/ipykernel_6572/3471649027.py", line 29, in <module>
    hypothesis = txt2annotation(hypothesis_path, annotation)
  File "/tmp/ipykernel_6572/733004344.py", line 4, in txt2annotation
    with open(path_txt, 'r') as f:
  File "/home/matias/Documents/UdeSA/CNC/diariziation_error_rate/der_env/lib/python3.10/site-packages/IPython/core/interactiveshell.py", line 324, in _modified_open
    return io_open(file, *args, **kwargs)
FileNotFoundError: [Errno 2] No such file or directory: '/home/matias/Documents/UdeSA/CNC/diariziation_error_rate/GENFI_Error_Rates/DER-predictions/Agus/07-047__FREE.txt'


Error in file: /home/matias/Documents/UdeSA/CNC/diariziation_error_rate/GENFI_Error_Rates/DER-ground-truth/Agus/07-004__FREE.txt
Traceback (most recent call last):
  File "/tmp/ipykernel_6572/3471649027.py", line 29, in <module>
    hypothesis = txt2annotation(hypothesis_path, annotation)
  File "/tmp/ipykernel_6572/733004344.py", line 4, in txt2annotation
    with open(path_txt, 'r') as f:
  File "/home/matias/Documents/UdeSA/CNC/diariziation_error_rate/der_env/lib/python3.10/site-packages/IPython/core/interactiveshell.py", line 324, in _modified_open
    return io_open(file, *args, **kwargs)
FileNotFoundError: [Errno 2] No such file or directory: '/home/matias/Documents/UdeSA/CNC/diariziation_error_rate/GENFI_Error_Rates/DER-predictions/Agus/07-004__FREE.txt'


Error in file: /home/matias/Documents/UdeSA/CNC/diariziation_error_rate/GENFI_Error_Rates/DER-ground-truth/Agus/15-010__FREE.txt
Traceback (most recent call last):
  File "/tmp/ipykernel_6572/3471649027.py", line 29, in <module>
    hypothesis = txt2annotation(hypothesis_path, annotation)
  File "/tmp/ipykernel_6572/733004344.py", line 4, in txt2annotation
    with open(path_txt, 'r') as f:
  File "/home/matias/Documents/UdeSA/CNC/diariziation_error_rate/der_env/lib/python3.10/site-packages/IPython/core/interactiveshell.py", line 324, in _modified_open
    return io_open(file, *args, **kwargs)
FileNotFoundError: [Errno 2] No such file or directory: '/home/matias/Documents/UdeSA/CNC/diariziation_error_rate/GENFI_Error_Rates/DER-predictions/Agus/15-010__FREE.txt'


